Workbook
Name pmt: 'Loan Scenarios'!$C$13

Sheet Sales Data
A1: Nokhba Electronics — Raw Transaction Export FY2022–FY2024
A2: Invoice_ID | B2: Date | C2: Client_Name | D2: Region | E2: Product_Category | F2: Qty | G2: Unit_Price_SAR | H2: Total_Sale_SAR | J2: Region | K2: LEN | M2: Product_Category | N2: LEN | P2: Client_Name
A3: INV-1038 | B3: 44564 | C3: Al Rajhi | D3: Dammam | E3: Accessories | F3: 37 | G3: 5450 | H3: =F3*G3 -> 201650 | J3: Riyadh | K3: =LEN(D3) -> 6 | M3: Accesories | N3: {=LEN(E3:E122)} -> 11 | P3: Al Rajhi
A4: INV-1028 | B4: 44569 | C4: Al Rajhi | D4: Dammam | E4: Accessories | F4: 12 | G4: 3750 | H4: =F4*G4 -> 45000 | J4: Jeda | K4: =LEN(D4) -> 6 | M4: Accessories | N4: 11 | P4: al Rajhi
A5: INV-1018 | B5: 44570 | C5: Al Rajhi | D5: Dammam | E5: Accessories | F5: 10 | G5: 6350 | H5: =F5*G5 -> 63500 | J5: Dammm | K5: =LEN(D5) -> 6 | M5: Laptop | N5: 11 | P5: Almarai
A6: INV-1008 | B6: 44586 | C6: Al Rajhi | D6: Dammam | E6: Accessories | F6: 137 | G6: 250 | H6: =F6*G6 -> 34250 | J6: Jubal | K6: =LEN(D6) -> 6 | M6: Phon | N6: 11 | P6: Aramco
A7: INV-1053 | B7: 44595 | C7: Al Rajhi | D7: Dammam | E7: Accessories | F7: 154 | G7: 300 | H7: =F7*G7 -> 46200 | J7: Khobar | K7: =LEN(D7) -> 6 | M7: Phone | N7: 11 | P7: SABIC
A8: INV-1078 | B8: 44595 | C8: Al Rajhi | D8: Dammam | E8: Accessories | F8: 7 | G8: 7400 | H8: =F8*G8 -> 51800 | J8: Dammam | K8: =LEN(D8) -> 6 | M8: Printer | N8: 11 | P8: STC
A9: INV-1068 | B9: 44605 | C9: Al Rajhi | D9: Dammam | E9: Accessories | F9: 6 | G9: 7500 | H9: =F9*G9 -> 45000 | J9: Jubail | K9: =LEN(D9) -> 6 | M9: Prnter | N9: 11
A10: INV-1048 | B10: 44609 | C10: Al Rajhi | D10: Dammam | E10: Accessories | F10: 12 | G10: 7500 | H10: =F10*G10 -> 90000 | J10: Jeddah | K10: =LEN(D10) -> 6 | M10: tablet | N10: 11
A11: INV-1073 | B11: 44614 | C11: Al Rajhi | D11: Dammam | E11: Accessories | F11: 18 | G11: 7600 | H11: =F11*G11 -> 136800 | J11: Khobr | K11: =LEN(D11) -> 6 | M11: Laptpp | N11: 11
A12: INV-1093 | B12: 44653 | C12: Al Rajhi | D12: Dammam | E12: Accessories | F12: 37 | G12: 6200 | H12: =F12*G12 -> 229400 | J12: Ryadh | K12: =LEN(D12) -> 6 | M12: Tabet | N12: 11
A13: INV-1118 | B13: 44654 | C13: Al Rajhi | D13: Dammam | E13: Accessories | F13: 133 | G13: 350 | H13: =F13*G13 -> 46550 | K13: =LEN(D13) -> 6 | M13: Acessories | N13: 11
A14: INV-1098 | B14: 44659 | C14: Al Rajhi | D14: Dammam | E14: Accessories | F14: 89 | G14: 350 | H14: =F14*G14 -> 31150 | K14: =LEN(D14) -> 6 | M14: Laptp | N14: 11
A15: INV-1088 | B15: 44663 | C15: Al Rajhi | D15: Dammam | E15: Accessories | F15: 7 | G15: 8550 | H15: =F15*G15 -> 59850 | K15: =LEN(D15) -> 6 | N15: 11
A16: INV-1043 | B16: 44668 | C16: Al Rajhi | D16: Dammam | E16: Accessories | F16: 7 | G16: 4450 | H16: =F16*G16 -> 31150 | K16: =LEN(D16) -> 6 | N16: 11
A17: INV-1063 | B17: 44684 | C17: Al Rajhi | D17: Dammam | E17: Accessories | F17: 32 | G17: 5500 | H17: =F17*G17 -> 176000 | K17: =LEN(D17) -> 6 | N17: 11
A18: INV-1103 | B18: 44703 | C18: Al Rajhi | D18: Dammam | E18: Accessories | F18: 106 | G18: 350 | H18: =F18*G18 -> 37100 | K18: =LEN(D18) -> 6 | N18: 11
A19: INV-1023 | B19: 44704 | C19: Al Rajhi | D19: Dammam | E19: Accessories | F19: 10 | G19: 3800 | H19: =F19*G19 -> 38000 | K19: =LEN(D19) -> 6 | N19: 11
A20: INV-1013 | B20: 44707 | C20: Al Rajhi | D20: Dammam | E20: Laptop | F20: 28 | G20: 2100 | H20: =F20*G20 -> 58800 | K20: =LEN(D20) -> 6 | N20: 6
A21: INV-1003 | B21: 44719 | C21: Al Rajhi | D21: Dammam | E21: Laptop | F21: 6 | G21: 4100 | H21: =F21*G21 -> 24600 | K21: =LEN(D21) -> 6 | N21: 6
A22: INV-1033 | B22: 44720 | C22: Al Rajhi | D22: Dammam | E22: Laptop | F22: 30 | G22: 2100 | H22: =F22*G22 -> 63000 | K22: =LEN(D22) -> 6 | N22: 6
A23: INV-1058 | B23: 44731 | C23: Al Rajhi | D23: Dammam | E23: Laptop | F23: 24 | G23: 2450 | H23: =F23*G23 -> 58800 | K23: =LEN(D23) -> 6 | N23: 6
A24: INV-1108 | B24: 44732 | C24: Al Rajhi | D24: Dammam | E24: Laptop | F24: 10 | G24: 5600 | H24: =F24*G24 -> 56000 | K24: =LEN(D24) -> 6 | N24: 6
A25: INV-1083 | B25: 44780 | C25: Al Rajhi | D25: Dammam | E25: Laptop | F25: 13 | G25: 3100 | H25: =F25*G25 -> 40300 | K25: =LEN(D25) -> 6 | N25: 6
A26: INV-1113 | B26: 44791 | C26: Al Rajhi | D26: Dammam | E26: Laptop | F26: 11 | G26: 2950 | H26: =F26*G26 -> 32450 | K26: =LEN(D26) -> 6 | N26: 6
A27: INV-1037 | B27: 44800 | C27: Almarai | D27: Jeddah | E27: Laptop | F27: 8 | G27: 3800 | H27: =F27*G27 -> 30400 | K27: =LEN(D27) -> 6 | N27: 6
A28: INV-1002 | B28: 44807 | C28: Almarai | D28: Jeddah | E28: Laptop | F28: 24 | G28: 5250 | H28: =F28*G28 -> 126000 | K28: =LEN(D28) -> 6 | N28: 6
A29: INV-1027 | B29: 44808 | C29: Almarai | D29: Jeddah | E29: Laptop | F29: 17 | G29: 2350 | H29: =F29*G29 -> 39950 | K29: =LEN(D29) -> 6 | N29: 6
A30: INV-1017 | B30: 44814 | C30: Almarai | D30: Jeddah | E30: Laptop | F30: 41 | G30: 4900 | H30: =F30*G30 -> 200900 | K30: =LEN(D30) -> 6 | N30: 6
... A59: INV-1044 | B59: 45158 | C59: Aramco | D59: Jubail | E59: Phone | F59: 11 | G59: 4950 | H59: =F59*G59 -> 54450 | K59: =LEN(D59) -> 6 | N59: 5
A60: INV-1069 | B60: 45163 | C60: Aramco | D60: Jubail | E60: Phone | F60: 20 | G60: 4350 | H60: =F60*G60 -> 87000 | K60: =LEN(D60) -> 6 | N60: 5
A61: INV-1049 | B61: 45171 | C61: Aramco | D61: Jubail | E61: Phone | F61: 6 | G61: 7100 | H61: =F61*G61 -> 42600 | K61: =LEN(D61) -> 6 | N61: 5
A62: INV-1074 | B62: 45185 | C62: Aramco | D62: Jubail | E62: Phone | F62: 10 | G62: 4950 | H62: =F62*G62 -> 49500 | K62: =LEN(D62) -> 6 | N62: 5
A63: INV-1064 | B63: 45188 | C63: Aramco | D63: Jubail | E63: Phone | F63: 24 | G63: 2450 | H63: =F63*G63 -> 58800 | K63: =LEN(D63) -> 6 | N63: 5
A64: INV-1094 | B64: 45201 | C64: Aramco | D64: Jubail | E64: Phone | F64: 13 | G64: 5000 | H64: =F64*G64 -> 65000 | K64: =LEN(D64) -> 6 | N64: 5
A65: INV-1109 | B65: 45206 | C65: Aramco | D65: Jubail | E65: Phone | F65: 15 | G65: 2850 | H65: =F65*G65 -> 42750 | K65: =LEN(D65) -> 6 | N65: 5
A66: INV-1114 | B66: 45208 | C66: Aramco | D66: Jubail | E66: Phone | F66: 13 | G66: 5350 | H66: =F66*G66 -> 69550 | K66: =LEN(D66) -> 6 | N66: 5
A67: INV-1119 | B67: 45233 | C67: Aramco | D67: Jubail | E67: Phone | F67: 7 | G67: 5000 | H67: =F67*G67 -> 35000 | K67: =LEN(D67) -> 6 | N67: 5
A68: INV-1099 | B68: 45237 | C68: Aramco | D68: Jubail | E68: Phone | F68: 45 | G68: 7000 | H68: =F68*G68 -> 315000 | K68: =LEN(D68) -> 6 | N68: 5
...

Sheet Pivot Table 
A1: Nokhba Electronics — Raw Transaction Export FY2022–FY2024
A2: Invoice_ID | B2: Date | C2: Client_Name | D2: Region | E2: Product_Category | F2: Qty | G2: Unit_Price_SAR | H2: Total_Sale_SAR | I2: Notes (explain how data has been cleaned)
A3: INV-1038 | B3: 44564 | C3: Al Rajhi | D3: Dammam | E3: Accessories | F3: 37 | G3: 5450 | H3: =F3*G3 -> 201650 | K3: Row Labels | L3: Sum of Total_Sale_SAR | P3: Row Labels | Q3: Sum of Total_Sale_SAR
A4: INV-1028 | B4: 44569 | C4: Al Rajhi | D4: Dammam | E4: Accessories | F4: 12 | G4: 3750 | H4: =F4*G4 -> 45000 | K4: Dammam | L4: 1697350 | P4: Accessories | Q4: 1363400
A5: INV-1018 | B5: 44570 | C5: Al Rajhi | D5: Dammam | E5: Accessories | F5: 10 | G5: 6350 | H5: =F5*G5 -> 63500 | K5: Jeddah | L5: 2252600 | P5: Laptop | Q5: 2586550
A6: INV-1008 | B6: 44586 | C6: Al Rajhi | D6: Dammam | E6: Accessories | F6: 137 | G6: 250 | H6: =F6*G6 -> 34250 | K6: Jubail | L6: 1616200 | P6: Phone | Q6: 1454700
A7: INV-1053 | B7: 44595 | C7: Al Rajhi | D7: Dammam | E7: Accessories | F7: 154 | G7: 300 | H7: =F7*G7 -> 46200 | K7: Khobar | L7: 2112400 | P7: Printer | Q7: 2161750
A8: INV-1078 | B8: 44595 | C8: Al Rajhi | D8: Dammam | E8: Accessories | F8: 7 | G8: 7400 | H8: =F8*G8 -> 51800 | K8: Riyadh | L8: 1949550 | P8: Tablet | Q8: 2061700
A9: INV-1068 | B9: 44605 | C9: Al Rajhi | D9: Dammam | E9: Accessories | F9: 6 | G9: 7500 | H9: =F9*G9 -> 45000
A10: INV-1048 | B10: 44609 | C10: Al Rajhi | D10: Dammam | E10: Accessories | F10: 12 | G10: 7500 | H10: =F10*G10 -> 90000
A11: INV-1073 | B11: 44614 | C11: Al Rajhi | D11: Dammam | E11: Accessories | F11: 18 | G11: 7600 | H11: =F11*G11 -> 136800
A12: INV-1093 | B12: 44653 | C12: Al Rajhi | D12: Dammam | E12: Accessories | F12: 37 | G12: 6200 | H12: =F12*G12 -> 229400
A13: INV-1118 | B13: 44654 | C13: Al Rajhi | D13: Dammam | E13: Accessories | F13: 133 | G13: 350 | H13: =F13*G13 -> 46550
A14: INV-1098 | B14: 44659 | C14: Al Rajhi | D14: Dammam | E14: Accessories | F14: 89 | G14: 350 | H14: =F14*G14 -> 31150
A15: INV-1088 | B15: 44663 | C15: Al Rajhi | D15: Dammam | E15: Accessories | F15: 7 | G15: 8550 | H15: =F15*G15 -> 59850
A16: INV-1043 | B16: 44668 | C16: Al Rajhi | D16: Dammam | E16: Accessories | F16: 7 | G16: 4450 | H16: =F16*G16 -> 31150
A17: INV-1063 | B17: 44684 | C17: Al Rajhi | D17: Dammam | E17: Accessories | F17: 32 | G17: 5500 | H17: =F17*G17 -> 176000
A18: INV-1103 | B18: 44703 | C18: Al Rajhi | D18: Dammam | E18: Accessories | F18: 106 | G18: 350 | H18: =F18*G18 -> 37100
A19: INV-1023 | B19: 44704 | C19: Al Rajhi | D19: Dammam | E19: Accessories | F19: 10 | G19: 3800 | H19: =F19*G19 -> 38000
A20: INV-1013 | B20: 44707 | C20: Al Rajhi | D20: Dammam | E20: Laptop | F20: 28 | G20: 2100 | H20: =F20*G20 -> 58800
A21: INV-1003 | B21: 44719 | C21: Al Rajhi | D21: Dammam | E21: Laptop | F21: 6 | G21: 4100 | H21: =F21*G21 -> 24600
A22: INV-1033 | B22: 44720 | C22: Al Rajhi | D22: Dammam | E22: Laptop | F22: 30 | G22: 2100 | H22: =F22*G22 -> 63000
A23: INV-1058 | B23: 44731 | C23: Al Rajhi | D23: Dammam | E23: Laptop | F23: 24 | G23: 2450 | H23: =F23*G23 -> 58800
A24: INV-1108 | B24: 44732 | C24: Al Rajhi | D24: Dammam | E24: Laptop | F24: 10 | G24: 5600 | H24: =F24*G24 -> 56000
A25: INV-1083 | B25: 44780 | C25: Al Rajhi | D25: Dammam | E25: Laptop | F25: 13 | G25: 3100 | H25: =F25*G25 -> 40300
A26: INV-1113 | B26: 44791 | C26: Al Rajhi | D26: Dammam | E26: Laptop | F26: 11 | G26: 2950 | H26: =F26*G26 -> 32450
A27: INV-1037 | B27: 44800 | C27: Almarai | D27: Jeddah | E27: Laptop | F27: 8 | G27: 3800 | H27: =F27*G27 -> 30400 | K27: Row Labels | L27: Sum of Total_Sale_SAR | P27: Row Labels | Q27: Sum of Total_Sale_SAR
A28: INV-1002 | B28: 44807 | C28: Almarai | D28: Jeddah | E28: Laptop | F28: 24 | G28: 5250 | H28: =F28*G28 -> 126000 | K28: Al Rajhi | L28: 1697350 | P28: 2022 | Q28: 2833100
A29: INV-1027 | B29: 44808 | C29: Almarai | D29: Jeddah | E29: Laptop | F29: 17 | G29: 2350 | H29: =F29*G29 -> 39950 | K29: Almarai | L29: 2252600 | P29: Mhrm | Q29: 344400
A30: INV-1017 | B30: 44814 | C30: Almarai | D30: Jeddah | E30: Laptop | F30: 41 | G30: 4900 | H30: =F30*G30 -> 200900 | K30: Aramco | L30: 1616200 | P30: Safr | Q30: 369800
A31: INV-1007 | B31: 44830 | C31: Almarai | D31: Jeddah | E31: Laptop | F31: 10 | G31: 2250 | H31: =F31*G31 -> 22500 | K31: Sabic | L31: 2112400 | P31: Rab. II | Q31: 398100
A32: INV-1032 | B32: 44841 | C32: Almarai | D32: Jeddah | E32: Laptop | F32: 8 | G32: 6550 | H32: =F32*G32 -> 52400 | K32: STC | L32: 1949550 | P32: Jmd. I | Q32: 309900
A33: INV-1022 | B33: 44858 | C33: Almarai | D33: Jeddah | E33: Laptop | F33: 22 | G33: 2100 | H33: =F33*G33 -> 46200 | P33: Jmd. II | Q33: 202400
A34: INV-1012 | B34: 44860 | C34: Almarai | D34: Jeddah | E34: Laptop | F34: 14 | G34: 6750 | H34: =F34*G34 -> 94500 | P34: Rajb | Q34: 105700
A35: INV-1077 | B35: 44900 | C35: Almarai | D35: Jeddah | E35: Laptop | F35: 5 | G35: 7400 | H35: =F35*G35 -> 37000 | P35: Shbn | Q35: 103150
A36: INV-1042 | B36: 44912 | C36: Almarai | D36: Jeddah | E36: Laptop | F36: 9 | G36: 7000 | H36: =F36*G36 -> 63000 | P36: Rmdn | Q36: 389350
A37: INV-1057 | B37: 44915 | C37: Almarai | D37: Jeddah | E37: Laptop | F37: 12 | G37: 4350 | H37: =F37*G37 -> 52200 | P37: Shwl | Q37: 193100
A38: INV-1072 | B38: 44930 | C38: Almarai | D38: Jeddah | E38: Laptop | F38: 38 | G38: 6050 | H38: =F38*G38 -> 229900 | P38: Dhuʻl-Q | Q38: 265000
A39: INV-1062 | B39: 44931 | C39: Almarai | D39: Jeddah | E39: Laptop | F39: 47 | G39: 5800 | H39: =F39*G39 -> 272600 | P39: Dhuʻl-H | Q39: 152200
A40: INV-1067 | B40: 44942 | C40: Almarai | D40: Jeddah | E40: Laptop | F40: 13 | G40: 4350 | H40: =F40*G40 -> 56550 | P40: 2023 | Q40: 3325000
...

Sheet Trial Balance
A1: Nokhba Electronics — Trial Balance (Pre-Closing) | FY2022–FY2024
A2: Note: Retained Earnings shown is BEGINNING balance (before current-year net income). Each year balances: Total Debits = Total Credits.
A3: Account_Code | B3: Account_Name | C3: Category | D3: FY2022_Debit | E3: FY2022_Credit | F3: FY2023_Debit | G3: FY2023_Credit | H3: FY2024_Debit | I3: FY2024_Credit
A4: 1001 | B4: Cash & Cash Equivalents | C4: Asset | D4: 2079012 | E4: 0 | F4: 2634935 | G4: 0 | H4: 3804402 | I4: 0
A5: 1100 | B5: Accounts Receivable | C5: Asset | D5: 387660 | E5: 0 | F5: 445380 | G5: 0 | H5: 503750 | I5: 0
A6: 1200 | B6: Inventory | C6: Asset | D6: 267228 | E6: 0 | F6: 308225 | G6: 0 | H6: 346788 | I6: 0
A7: 1500 | B7: Fixed Assets (Net) | C7: Asset | D7: 512500 | E7: 0 | F7: 735000 | G7: 0 | H7: 751080 | I7: 0
A8: 2001 | B8: Accounts Payable | C8: Liability | D8: 0 | E8: 285000 | F8: 0 | G8: 342000 | H8: 0 | I8: 398000
A9: 2100 | B9: Short-term Loans | C9: Liability | D9: 0 | E9: 320000 | F9: 0 | G9: 380000 | H9: 0 | I9: 755000
A10: 3001 | B10: Share Capital | C10: Equity | D10: 0 | E10: 2000000 | F10: 0 | G10: 2000000 | H10: 0 | I10: 2000000
A11: 3002 | B11: Retained Earnings (Beg.) | C11: Equity | D11: 0 | E11: 0 | F11: 0 | G11: 641400 | H11: 0 | I11: 1401540
A12: 4001 | B12: Sales Revenue | C12: Revenue | D12: 0 | E12: 2855000 | F12: 0 | G12: 3293000 | H12: 0 | I12: 3705000
A13: 4002 | B13: Service Revenue | C13: Revenue | D13: 0 | E13: 127000 | F13: 0 | G13: 133000 | H13: 0 | I13: 170000
A14: 5001 | B14: Cost of Goods Sold | C14: COGS | D14: 1484600 | E14: 0 | F14: 1712360 | G14: 0 | H14: 1926600 | I14: 0
A15: 5100 | B15: Salaries Expense | C15: Operating Expense | D15: 480000 | E15: 0 | F15: 516000 | G15: 0 | H15: 558000 | I15: 0
... A21: 5700 | B21: Miscellaneous Expense | C21: Operating Expense | D21: 15000 | E21: 0 | F21: 17000 | G21: 0 | H21: 19000 | I21: 0
B22: TOTALS | D22: =SUM(D4:D21) -> 5587000 | E22: =SUM(E4:E21) -> 5587000 | F22: =SUM(F4:F21) -> 6789400 | G22: =SUM(G4:G21) -> 6789400 | H22: =SUM(H4:H21) -> 8429540 | I22: =SUM(I4:I21) -> 8429540

Sheet Common size analysis 
C1: 2022 | D1: 20.22 | E1: 2023 | F1: 20.23 | G1: 2024 | H1: 20.24
A2: Net Sales | C2: ='Trial Balance'!E12+'Trial Balance'!E13 -> 2982000 | D2: =C2/$C$2 -> 1 | E2: ='Trial Balance'!G12+'Trial Balance'!G13 -> 3426000 | F2: =E2/$E$2 -> 1 | G2: ='Trial Balance'!I12+'Trial Balance'!I13 -> 3875000 | H2: =G2/$G$2 -> 1
A3: Cost of Goods Sold | C3: ='Trial Balance'!D14 -> 1484600 | D3: =C3/$C$2 -> 0.49785379 | E3: ='Trial Balance'!F14 -> 1712360 | F3: =E3/$E$2 -> 0.49981319 | G3: ='Trial Balance'!H14 -> 1926600 | H3: =G3/$G$2 -> 0.4971871
A4: Gross Profit | C4: =C2-C3 -> 1497400 | D4: =C4/$C$2 -> 0.50214621 | E4: =E2-E3 -> 1713640 | F4: =E4/$E$2 -> 0.50018681 | G4: =G2-G3 -> 1948400 | H4: =G4/$G$2 -> 0.5028129
A5: Operating Expenses | D5: =C5/$C$2 -> 0 | F5: =E5/$E$2 -> 0 | H5: =G5/$G$2 -> 0
B6: Salaries Expense | C6: ='Trial Balance'!D15 -> 480000 | D6: =C6/$C$2 -> 0.16096579 | E6: ='Trial Balance'!F15 -> 516000 | F6: =E6/$E$2 -> 0.15061296 | G6: ='Trial Balance'!H15 -> 558000 | H6: =G6/$G$2 -> 0.144
B7: Rent Expense | C7: ='Trial Balance'!D16 -> 195000 | D7: =C7/$C$2 -> 0.065392354 | E7: ='Trial Balance'!F16 -> 210000 | F7: =E7/$E$2 -> 0.061295972 | G7: ='Trial Balance'!H16 -> 225000 | H7: =G7/$G$2 -> 0.058064516
B8: Utilities Expense | C8: ='Trial Balance'!D17 -> 42000 | D8: =C8/$C$2 -> 0.014084507 | E8: ='Trial Balance'!F17 -> 46000 | F8: =E8/$E$2 -> 0.013426737 | G8: ='Trial Balance'!H17 -> 51000 | H8: =G8/$G$2 -> 0.01316129
B9: Marketing Expense | C9: ='Trial Balance'!D18 -> 38000 | D9: =C9/$C$2 -> 0.012743125 | E9: ='Trial Balance'!F18 -> 45000 | F9: =E9/$E$2 -> 0.013134851 | G9: ='Trial Balance'!H18 -> 55000 | H9: =G9/$G$2 -> 0.014193548
B10: Depreciation Expense | C10: ='Trial Balance'!D19 -> 67500 | D10: =C10/$C$2 -> 0.022635815 | E10: ='Trial Balance'!F19 -> 97500 | F10: =E10/$E$2 -> 0.028458844 | G10: ='Trial Balance'!H19 -> 163920 | H10: =G10/$G$2 -> 0.042301935
B11: Miscellaneous Expense | C11: ='Trial Balance'!D21 -> 15000 | D11: =C11/$C$2 -> 0.0050301811 | E11: ='Trial Balance'!F21 -> 17000 | F11: =E11/$E$2 -> 0.0049620549 | G11: ='Trial Balance'!H21 -> 19000 | H11: =G11/$G$2 -> 0.0049032258
A12: Total Operating Expenses | C12: =SUM(C6:C11) -> 837500 | D12: =C12/$C$2 -> 0.28085178 | E12: =SUM(E6:E11) -> 931500 | F12: =E12/$E$2 -> 0.27189142 | G12: =SUM(G6:G11) -> 1071920 | H12: =G12/$G$2 -> 0.27662452
A13: Operating Income | C13: =C4-C12 -> 659900 | D13: =C13/$C$2 -> 0.22129443 | E13: =E4-E12 -> 782140 | F13: =E13/$E$2 -> 0.22829539 | G13: =G4-G12 -> 876480 | H13: =G13/$G$2 -> 0.22618839
A14: Interest Expense | C14: ='Trial Balance'!D20 -> 18500 | D14: =C14/$C$2 -> 0.00620389 | E14: ='Trial Balance'!F20 -> 22000 | F14: =E14/$E$2 -> 0.0064214828 | G14: ='Trial Balance'!H20 -> 25000 | H14: =G14/$G$2 -> 0.0064516129
A15: Net Income | C15: =C13-C14 -> 641400 | D15: =C15/$C$2 -> 0.21509054 | E15: =E13-E14 -> 760140 | F15: =E15/$E$2 -> 0.22187391 | G15: =G13-G14 -> 851480 | H15: =G15/$G$2 -> 0.21973677

Sheet Fixed Assets Register
A1: Nokhba Electronics — Fixed Asset Register (as at 31 December 2024)
A2: Asset ID | B2: Asset Name | C2: Branch | D2: Category | E2: Purchase Date | F2: Cost SAR | G2: Useful Life Yrs | H2: Salvage Value SAR | I2: Depreciation Method | J2: Annual Depr SAR | K2: Accumulated Depr to 2024 | L2: Net Book Value (NBV)2024 | M2: Status
A3: FA-001 | B3: Delivery Vehicles - Fleet A | C3: Riyadh | D3: Vehicles | E3: 44593 | F3: 580000 | G3: 8 | H3: 40000 | I3: Straight-Line | K3: 202500 | M3: Active
A4: FA-002 | B4: Warehouse Shelving System | C4: Jeddah | D4: Equipment | E4: 44929 | F4: 320000 | G4: 10 | H4: 20000 | I4: Straight-Line | J4: =(F4-H4)/G4 -> 30000 | K4: =I14 -> 60000 | L4: =F4-K4 -> 260000 | M4: Active
A5: FA-003 | B5: POS Systems (10 units) | C5: Riyadh | D5: IT Equipment | E5: 45292 | F5: 180000 | G5: 5 | H5: 18000 | I5: Declining Balance | J5: =DB(F5,H5,G5,1) -> 66420 | K5: 66420 | L5: =F5-K5 -> 113580 | M5: Active
A7: * Accum_Depr_to_2024: Multiply Annual_Depr by years in service. Verify using correct Excel depreciation functions.
A10: FA-001 — Delivery Vehicles – Fleet A (SLN) | F10: FA-002 — Warehouse Shelving System (SLN) | K10: FA-003 — POS Systems (10 units) (DB)
A11: Cost: SAR 580,000 | Salvage: SAR 40,000 | Life: 8 years | Purchase: 2022 | F11: Cost: SAR 320,000 | Salvage: SAR 20,000 | Life: 10 years | Purchase: 2023 | K11: Cost: SAR 180,000 | Salvage: SAR 18,000 | Life: 5 years | Purchase: 2024
A12: Year | B12: Opening NBV | C12: Depr. Expenses | D12: Accumulated. Depr. | E12: Closing NBV | F12: Year | G12: Opening NBV | H12: Depr. Expenses | I12: =D12 -> Accumulated. Depr. | J12: Closing NBV | K12: Year | L12: Opening NBV | M12: Depr. Expenses | N12: =I12 -> Accumulated. Depr. | O12: Closing NBV
A13: 2022 | B13: 580000 | C13: =(580000-40000)/8 -> 67500 | D13: =(580000-40000)/8 -> 67500 | E13: =B13-C13 -> 512500 | F13: 2023 | G13: 320000 | H13: =(G13-20000)/10 -> 30000 | I13: =H13 -> 30000 | J13: =G13-H13 -> 290000 | K13: 2024 | L13: 180000 | M13: =DB(F5,H5,G5,1) -> 66420 | N13: =M13 -> 66420 | O13: =L13-M13 -> 113580
A14: 2023 | B14: =E13 -> 512500 | C14: =(580000-40000)/8 -> 67500 | D14: =D13+C14 -> 135000 | E14: =B14-C14 -> 445000 | F14: 2024 | G14: =J13 -> 290000 | H14: =H13 -> 30000 | I14: =I13+H14 -> 60000 | J14: =G14-H14 -> 260000 | K14: 2025 | L14: =O13 -> 113580 | M14: =DB(F5,H5,G5,2) -> 41911.02 | N14: =N13+M14 -> 108331.02 | O14: =L14-M14 -> 71668.98
A15: 2024 | B15: =E14 -> 445000 | C15: =(580000-40000)/8 -> 67500 | D15: =D14+C15 -> 202500 | E15: =B15-C15 -> 377500 | F15: 2025 | G15: =J14 -> 260000 | H15: =H14 -> 30000 | I15: =I14+H15 -> 90000 | J15: =G15-H15 -> 230000 | K15: 2026 | L15: =O14 -> 71668.98 | M15: =DB(F5,H5,G5,3) -> 26445.854 | N15: =N14+M15 -> 134776.87 | O15: =L15-M15 -> 45223.126
A16: 2025 | B16: =E15 -> 377500 | C16: =(580000-40000)/8 -> 67500 | D16: =D15+C16 -> 270000 | E16: =B16-C16 -> 310000 | F16: 2026 | G16: =J15 -> 230000 | H16: =H15 -> 30000 | I16: =I15+H16 -> 120000 | J16: =G16-H16 -> 200000 | K16: 2027 | L16: =O15 -> 45223.126 | M16: =DB(F5,H5,G5,4) -> 16687.334 | N16: =N15+M16 -> 151464.21 | O16: =L16-M16 -> 28535.793
A17: 2026 | B17: =E16 -> 310000 | C17: =(580000-40000)/8 -> 67500 | D17: =D16+C17 -> 337500 | E17: =B17-C17 -> 242500 | F17: 2027 | G17: =J16 -> 200000 | H17: =H16 -> 30000 | I17: =I16+H17 -> 150000 | J17: =G17-H17 -> 170000 | K17: 2028 | L17: =O16 -> 28535.793 | M17: =DB(F5,H5,G5,5) -> 10529.708 | N17: =N16+M17 -> 161993.91 | O17: =L17-M17 -> 18006.085
A18: 2027 | B18: =E17 -> 242500 | C18: =(580000-40000)/8 -> 67500 | D18: =D17+C18 -> 405000 | E18: =B18-C18 -> 175000 | F18: 2028 | G18: =J17 -> 170000 | H18: =H17 -> 30000 | I18: =I17+H18 -> 180000 | J18: =G18-H18 -> 140000
A19: 2028 | B19: =E18 -> 175000 | C19: =(580000-40000)/8 -> 67500 | D19: =D18+C19 -> 472500 | E19: =B19-C19 -> 107500 | F19: 2029 | G19: =J18 -> 140000 | H19: =H18 -> 30000 | I19: =I18+H19 -> 210000 | J19: =G19-H19 -> 110000
A20: 2029 | B20: =E19 -> 107500 | C20: =(580000-40000)/8 -> 67500 | D20: =D19+C20 -> 540000 | E20: =B20-C20 -> 40000 | F20: 2030 | G20: =J19 -> 110000 | H20: =H19 -> 30000 | I20: =I19+H20 -> 240000 | J20: =G20-H20 -> 80000
F21: 2031 | G21: =J20 -> 80000 | H21: =H20 -> 30000 | I21: =I20+H21 -> 270000 | J21: =G21-H21 -> 50000
F22: 2032 | G22: =J21 -> 50000 | H22: =H21 -> 30000 | I22: =I21+H22 -> 300000 | J22: =G22-H22 -> 20000

Sheet Payroll Register
A1: Nokhba Electronics — Payroll Register (December 2024)
A2: Employee ID | B2: Employee Name | C2: Department | D2: Branch | E2: Position | F2: Basic Salary SAR | G2: Housing Allowance SAR | H2: Transport Allowance SAR | I2: Gross Salary SAR | J2: GOSI Deduction SAR( XX % of Basic) | K2: Income Tax SAR | L2: Net Salary SAR | M2: Employment Type | N2: Start Date
A3: EMP-001 | B3: Ahmad Al-Ghamdi | C3: Sales | D3: Riyadh | E3: Senior Sales Manager | F3: 18000 | G3: 4500 | H3: 1200 | I3: =SUM(F3+G3+H3) -> 23700 | J3: =(F3+G3)*0.1 -> 2250 | K3: 0 | L3: =I3-J3-K3 -> 21450 | M3: Full-time | N3: 03/01/2018
A4: EMP-002 | B4: Sara Mohammed | C4: Sales | D4: Jeddah | E4: Sales Manager | F4: 15000 | G4: 3750 | H4: 1000 | I4: =SUM(F4+G4+H4) -> 19750 | J4: =(F4+G4)*0.1 -> 1875 | K4: 0 | L4: =I4-J4-K4 -> 17875 | M4: Full-time | N4: 07/15/2019
A5: EMP-003 | B5: Khalid Ibrahim | C5: Sales | D5: Dammam | E5: Branch Sales Manager | F5: 14000 | G5: 3500 | H5: 1000 | I5: =SUM(F5+G5+H5) -> 18500 | J5: =(F5+G5)*0.1 -> 1750 | K5: 0 | L5: =I5-J5-K5 -> 16750 | M5: Full-time | N5: 01/20/2020
A6: EMP-004 | B6: Fatima Al-Rashidi | C6: Finance | D6: Riyadh | E6: CFO | F6: 28000 | G6: 7000 | H6: 1500 | I6: =SUM(F6+G6+H6) -> 36500 | J6: =(F6+G6)*0.1 -> 3500 | K6: 0 | L6: =I6-J6-K6 -> 33000 | M6: Full-time | N6: 06/01/2016
A7: EMP-005 | B7: Mohammed Al-Zahrani | C7: Finance | D7: Riyadh | E7: Senior Accountant | F7: 16000 | G7: 4000 | H7: 1000 | I7: =SUM(F7+G7+H7) -> 21000 | J7: =(F7+G7)*0.1 -> 2000 | K7: 0 | L7: =I7-J7-K7 -> 19000 | M7: Full-time | N7: 09/10/2019
A8: EMP-006 | B8: Nora Al-Qahtani | C8: HR | D8: RIYADH | E8: HR Manager | F8: 17000 | G8: 4250 | H8: 1000 | I8: =SUM(F8+G8+H8) -> 22250 | J8: =(F8+G8)*0.1 -> 2125 | K8: 0 | L8: =I8-J8-K8 -> 20125 | M8: Full-time | N8: 02/01/2020
A9: EMP-007 | B9: Abdullah Salem | C9: Operations | D9: Dammam | E9: Warehouse Supervisor | F9: 12000 | G9: 3000 | H9: 800 | I9: =SUM(F9+G9+H9) -> 15800 | J9: =(F9+G9)*0.1 -> 1500 | K9: 0 | L9: =I9-J9-K9 -> 14300 | M9: Full-time | N9: 11/15/2021
A10: EMP-008 | B10: Reem Al-Harbi | C10: Marketing | D10: Riyadh | E10: Marketing Manager | F10: 19000 | G10: 4750 | H10: 1200 | I10: =SUM(F10+G10+H10) -> 24950 | J10: =(F10+G10)*0.1 -> 2375 | K10: 0 | L10: =I10-J10-K10 -> 22575 | M10: Full-time | N10: 04/01/2021
A11: EMP-009 | B11: Omar Al-Otaibi | C11: IT | D11: Riyadh | E11: IT Manager | F11: 22000 | G11: 5500 | H11: 1200 | I11: =SUM(F11+G11+H11) -> 28700 | J11: =(F11+G11)*0.1 -> 2750 | K11: 0 | L11: =I11-J11-K11 -> 25950 | M11: Full-time | N11: 08/01/2022
A12: EMP-010 | B12: Hessa Al-Dossari | C12: Sales | D12: jeddah | E12: Sales Executive | F12: 9500 | G12: 2375 | H12: 700 | I12: =SUM(F12+G12+H12) -> 12575 | J12: =(F12+G12)*0.1 -> 1187.5 | K12: 0 | L12: =I12-J12-K12 -> 11387.5 | M12: Full-time | N12: 05/20/2023
A13: EMP-011 | B13: Turki Al-Shehri | C13: Operations | D13: Riyadh | E13: Driver | F13: 6500 | G13: 1625 | H13: 650 | I13: =SUM(F13+G13+H13) -> 8775 | J13: =(F13+G13)*0.1 -> 812.5 | K13: 0 | L13: =I13-J13-K13 -> 7962.5 | M13: Full-time | N13: 01/10/2020
A14: EMP-012 | B14: Aisha Al-Johani | C14: Finance | D14: Jeddah | E14: Accountant | F14: 13500 | G14: 3375 | H14: 900 | I14: =SUM(F14+G14+H14) -> 17775 | J14: =(F14+G14)*0.1 -> 1687.5 | K14: 0 | L14: =I14-J14-K14 -> 16087.5 | M14: Full-time | N14: 03/15/2022
A15: EMP-013 | B15: Saad Al-Mutairi | C15: Sales | D15: Dammam | E15: Sales Executive | F15: 9000 | G15: 2250 | H15: 700 | I15: =SUM(F15+G15+H15) -> 11950 | J15: =(F15+G15)*0.1 -> 1125 | K15: 0 | L15: =I15-J15-K15 -> 10825 | M15: Full-time | N15: 09/01/2023
A16: EMP-014 | B16: Lina Al-Ghamdi | C16: Marketing | D16: Riyadh | E16: Social Media Specialist | F16: 10500 | G16: 2625 | I16: =SUM(F16+G16+H16) -> 13125 | J16: =(F16+G16)*0.1 -> 1312.5 | K16: 0 | L16: =I16-J16-K16 -> 11812.5 | M16: Part-time | N16: 06/01/2024

Sheet Scenario Summary
B2: Scenario Summary
D3: Current Values: | E3: base case | F3: optimistic case | G3: pessimistic case
E4: Created by Joori AlQahtani on 01/05/2026 Modified by Joori AlQahtani on 01/05/2026 | F4: Created by Joori AlQahtani on 01/05/2026 Modified by Joori AlQahtani on 01/05/2026 | G4: Created by Joori AlQahtani on 01/05/2026 Modified by Joori AlQahtani on 01/05/2026
B5: Changing Cells:
C6: $C$10 | D6: 0.045 | E6: 0.06 | F6: 0.045 | G6: 0.08
C7: $C$11 | D7: 5 | E7: 5 | F7: 5 | G7: 7
C8: $C$12 | D8: 60 | E8: 60 | F8: 60 | G8: 84
B9: Result Cells:
C10: $C$14 | D10: 1677871.7 | E10: 1739952.1 | F10: 1677871.7 | G10: 1963863
B11: Notes: Current Values column represents values of changing cells at
B12: time Scenario Summary Report was created. Changing cells for each
B13: scenario are highlighted in gray.

Sheet Loan Scenarios
A1: Nokhba Electronics — Expansion Financing: Loan Scenario Parameters
A2: The company requires a SAR 1,500,000 bank loan to fund its regional expansion. Management has identified three possible financing scenarios. Use the parameters below to build Scenario tool in Excel.
A4: PMT Claculation Formula Base Case | B4: =PMT(6%/12,60,C9) -> -28999.202
A5: PMT Claculation Formula Optimistic Case | B5: =PMT(4.5%/12,60,C9) -> -27964.529
A6: PMT Claculation Formula Pessimistic Case | B6: =PMT(8%/12,84,C9) -> -23379.322
A8: Loan cases
A9: Loan Amount (SAR) | C9: 1500000
A10: Annual Interest Rate | C10: 0.045
A11: Loan Term (Years) | C11: 5
A12: Number of Monthly Payments | C12: 60
A13: Monthly PMT (SAR) | C13: =PMT(C10/12,C12,C9) -> -27964.529
A14: Total Repayment (SAR) | C14: =C12*(-pmt) -> 1677871.7
